<?xml version="1.0" encoding="utf-8"?>
<robot
  name="rml_63_description">
  <link
    name="base_link">
    <inertial>
      <origin
        xyz="0.001418 -0.00010076 0.050086"
        rpy="0 0 0" />
      <mass
        value="0.66248" />
      <inertia
        ixx="0.00099641"
        ixy="3.2555E-06"
        ixz="-1.005E-05"
        iyy="0.0010163"
        iyz="1.2819E-06"
        izz="0.00067925" />
    </inertial>
    <visual>
      <origin
        xyz="0 0 0"
        rpy="0 0 0" />
      <geometry>
        <mesh
          filename="package://rm_description/meshes/rm_63_arm/base_link.STL" />
      </geometry>
      <material
        name="">
        <color
          rgba="1 1 1 1" />
      </material>
    </visual>
    <collision>
      <origin
        xyz="0 0 0"
        rpy="0 0 0" />
      <geometry>
        <mesh
          filename="package://rm_description/meshes/rm_63_arm/base_link.STL" />
      </geometry>
    </collision>
  </link>
  <link
    name="link1">
    <inertial>
      <origin
        xyz="-0.030909 -0.0013023 -0.0053121"
        rpy="0 0 0" />
      <mass
        value="1.7668" />
      <inertia
        ixx="0.0014534"
        ixy="-0.00017578"
        ixz="0.0002802"
        iyy="0.0043772"
        iyz="1.7209E-05"
        izz="0.0040911" />
    </inertial>
    <visual>
      <origin
        xyz="0 0 0"
        rpy="0 0 0" />
      <geometry>
        <mesh
          filename="package://rm_description/meshes/rm_63_arm/link1.STL" />
      </geometry>
      <material
        name="">
        <color
          rgba="1 1 1 1" />
      </material>
    </visual>
    <collision>
      <origin
        xyz="0 0 0"
        rpy="0 0 0" />
      <geometry>
        <mesh
          filename="package://rm_description/meshes/rm_63_arm/link1.STL" />
      </geometry>
    </collision>
  </link>
  <joint
    name="joint1"
    type="revolute">
    <origin
      xyz="0 0 0.172"
      rpy="0 0 0" />
    <parent
      link="base_link" />
    <child
      link="link1" />
    <axis
      xyz="0 0 1" />
    <limit
      lower="-3.107"
      upper="3.107"
      effort="100"
      velocity="1" />
  </joint>
  <link
    name="link2">
    <inertial>
      <origin
        xyz="0.16852 9.8217E-07 -0.077258"
        rpy="0 0 0" />
      <mass
        value="4.3415" />
      <inertia
        ixx="0.0028306"
        ixy="3.3846E-07"
        ixz="4.0484E-06"
        iyy="0.075435"
        iyz="-3.3974E-08"
        izz="0.075923" />
    </inertial>
    <visual>
      <origin
        xyz="0 0 0"
        rpy="0 0 0" />
      <geometry>
        <mesh
          filename="package://rm_description/meshes/rm_63_arm/link2.STL" />
      </geometry>
      <material
        name="">
        <color
          rgba="0.86667 0.86667 0.8902 1" />
      </material>
    </visual>
    <collision>
      <origin
        xyz="0 0 0"
        rpy="0 0 0" />
      <geometry>
        <mesh
          filename="package://rm_description/meshes/rm_63_arm/link2.STL" />
      </geometry>
    </collision>
  </link>
  <joint
    name="joint2"
    type="revolute">
    <origin
      xyz="-0.086 0 0"
      rpy="-1.5708 -1.5708 0" />
    <parent
      link="link1" />
    <child
      link="link2" />
    <axis
      xyz="0 0 1" />
    <limit
      lower="-3.107"
      upper="3.107"
      effort="100"
      velocity="1" />
  </joint>
  <link
    name="link3">
    <inertial>
      <origin
        xyz="0.034488 -0.010948 -0.0056239"
        rpy="0 0 0" />
      <mass
        value="1.7286" />
      <inertia
        ixx="0.0014154"
        ixy="0.00068025"
        ixz="-0.00043307"
        iyy="0.0026049"
        iyz="0.00017201"
        izz="0.0028551" />
    </inertial>
    <visual>
      <origin
        xyz="0 0 0"
        rpy="0 0 0" />
      <geometry>
        <mesh
          filename="package://rm_description/meshes/rm_63_arm/link3.STL" />
      </geometry>
      <material
        name="">
        <color
          rgba="0.86667 0.86667 0.8902 1" />
      </material>
    </visual>
    <collision>
      <origin
        xyz="0 0 0"
        rpy="0 0 0" />
      <geometry>
        <mesh
          filename="package://rm_description/meshes/rm_63_arm/link3.STL" />
      </geometry>
    </collision>
  </link>
  <joint
    name="joint3"
    type="revolute">
    <origin
      xyz="0.38 0 0"
      rpy="0 0 1.5708" />
    <parent
      link="link2" />
    <child
      link="link3" />
    <axis
      xyz="0 0 1" />
    <limit
      lower="-3.107"
      upper="2.531"
      effort="100"
      velocity="1" />
  </joint>
  <link
    name="link4">
    <inertial>
      <origin
        xyz="4.1778E-07 -0.030483 -0.19739"
        rpy="0 0 0" />
      <mass
        value="2.4734" />
      <inertia
        ixx="0.02602"
        ixy="-1.1659E-07"
        ixz="3.1323E-07"
        iyy="0.024375"
        iyz="0.0061661"
        izz="0.002958" />
    </inertial>
    <visual>
      <origin
        xyz="0 0 0"
        rpy="0 0 0" />
      <geometry>
        <mesh
          filename="package://rm_description/meshes/rm_63_arm/link4.STL" />
      </geometry>
      <material
        name="">
        <color
          rgba="0.86667 0.86667 0.8902 1" />
      </material>
    </visual>
    <collision>
      <origin
        xyz="0 0 0"
        rpy="0 0 0" />
      <geometry>
        <mesh
          filename="package://rm_description/meshes/rm_63_arm/link4.STL" />
      </geometry>
    </collision>
  </link>
  <joint
    name="joint4"
    type="revolute">
    <origin
      xyz="0.069 -0.405 0"
      rpy="1.5708 0 0" />
    <parent
      link="link3" />
    <child
      link="link4" />
    <axis
      xyz="0 0 1" />
    <limit
      lower="-3.107"
      upper="3.107"
      effort="100"
      velocity="1" />
  </joint>
  <link
    name="link5">
    <inertial>
      <origin
        xyz="5.2596E-06 0.025125 -0.0072574"
        rpy="0 0 0" />
      <mass
        value="0.93162" />
      <inertia
        ixx="0.0012563"
        ixy="-1.8115E-08"
        ixz="-2.4669E-09"
        iyy="0.0005379"
        iyz="-0.00017339"
        izz="0.0011134" />
    </inertial>
    <visual>
      <origin
        xyz="0 0 0"
        rpy="0 0 0" />
      <geometry>
        <mesh
          filename="package://rm_description/meshes/rm_63_arm/link5.STL" />
      </geometry>
      <material
        name="">
        <color
          rgba="0.86667 0.86667 0.8902 1" />
      </material>
    </visual>
    <collision>
      <origin
        xyz="0 0 0"
        rpy="0 0 0" />
      <geometry>
        <mesh
          filename="package://rm_description/meshes/rm_63_arm/link5.STL" />
      </geometry>
    </collision>
  </link>
  <joint
    name="joint5"
    type="revolute">
    <origin
      xyz="0 0 0"
      rpy="1.5708 0 3.1416" />
    <parent
      link="link4" />
    <child
      link="link5" />
    <axis
      xyz="0 0 1" />
    <limit
      lower="-3.107"
      upper="3.107"
      effort="100"
      velocity="1" />
  </joint>
  <link
    name="link6">
    <inertial>
      <origin
        xyz="-0.00092265 9.4391E-05 -0.012705"
        rpy="0 0 0" />
      <mass
        value="0.065037" />
      <inertia
        ixx="2.1144E-05"
        ixy="-2.2803E-08"
        ixz="2.5415E-08"
        iyy="1.8109E-05"
        iyz="1.0256E-08"
        izz="3.19E-05" />
    </inertial>
    <visual>
      <origin
        xyz="0 0 0"
        rpy="0 0 0" />
      <geometry>
        <mesh
          filename="package://rm_description/meshes/rm_63_arm/link6.STL" />
      </geometry>
      <material
        name="">
        <color
          rgba="1 1 1 1" />
      </material>
    </visual>
    <collision>
      <origin
        xyz="0 0 0"
        rpy="0 0 0" />
      <geometry>
        <mesh
          filename="package://rm_description/meshes/rm_63_arm/link6.STL" />
      </geometry>
    </collision>
  </link>
  <joint
    name="joint6"
    type="revolute">
    <origin
      xyz="-0.00010308 0.115 -0.00010734"
      rpy="1.5708 0 3.1416" />
    <parent
      link="link5" />
    <child
      link="link6" />
    <axis
      xyz="0 0 1" />
    <limit
      lower="-3.14"
      upper="3.14"
      effort="100"
      velocity="1" />
  </joint>


     <joint
      name="fixed_plate"
      type="fixed">
      <origin
        xyz="0 0 0"
        rpy="0 0 1.5708" />
      <parent
        link="link6" />
      <child
        link="S4C2_baselink" />
      <axis
        xyz="0 0 1" />
    </joint>

    <link
      name="S4C2_baselink">
      <inertial>
        <origin
          xyz="1.5645E-05 -4.1838E-06 0.038"
          rpy="0 0 0" />
        <mass
          value="0.00001" />
        <inertia
          ixx="5.095E-05"
          ixy="-7.3167E-13"
          ixz="2.0229E-08"
          iyy="6.0883E-05"
          iyz="-4.5583E-09"
          izz="1.933E-05" />
      </inertial>
      <visual>
        <origin
          xyz="0 0 0"
          rpy="0 0 0" />
        <geometry>
          <mesh
            filename="package://rm_description/meshes/rm_63_arm/S4C2_baselink.STL" />
        </geometry>
        <material
          name="">
          <color
            rgba="0.75294 0.75294 0.75294 1" />
        </material>
      </visual>
      <collision>
        <origin
          xyz="0 0 0"
          rpy="0 0 0" />
        <geometry>
          <mesh
            filename="package://rm_description/meshes/rm_63_arm/S4C2_baselink.STL" />
        </geometry>
      </collision>
    </link>
    <link
      name="S4C2_Link1">
      <inertial>
        <origin
          xyz="0.0087669 0.009 0.013992"
          rpy="0 0 0" />
        <mass
          value="0.00001" />
        <inertia
          ixx="5.1061E-07"
          ixy="-8.6739E-19"
          ixz="-2.508E-07"
          iyy="5.7398E-07"
          iyz="-1.3667E-18"
          izz="2.6747E-07" />
      </inertial>
      <visual>
        <origin
          xyz="0 0 0"
          rpy="0 0 0" />
        <geometry>
          <mesh
            filename="package://rm_description/meshes/rm_63_arm/S4C2_Link1.STL" />
        </geometry>
        <material
          name="">
          <color
            rgba="0.75294 0.75294 0.75294 1" />
        </material>
      </visual>
      <collision>
        <origin
          xyz="0 0 0"
          rpy="0 0 0" />
        <geometry>
          <mesh
            filename="package://rm_description/meshes/rm_63_arm/S4C2_Link1.STL" />
        </geometry>
      </collision>
    </link>
    <joint
      name="S4C2_Joint1"
      type="fixed">
      <origin
        xyz="-0.04 -0.009 0.079"
        rpy="0 0 0" />
      <parent
        link="S4C2_baselink" />
      <child
        link="S4C2_Link1" />
      <axis
        xyz="0 -1 0" />
      <limit
        lower="0"
        upper="0.82"
        effort="1"
        velocity="1" />
      
    </joint>
    <link
      name="S4C2_Link5">
      <inertial>
        <origin
          xyz="0.011864 0.006 0.011367"
          rpy="0 0 0" />
        <mass
          value="0.000045068" />
        <inertia
          ixx="5.1288E-07"
          ixy="-9.8137E-14"
          ixz="-9.4703E-08"
          iyy="5.3203E-07"
          iyz="-6.212E-14"
          izz="2.009E-07" />
      </inertial>
      <visual>
        <origin
          xyz="0 0 0"
          rpy="0 0 0" />
        <geometry>
          <mesh
            filename="package://rm_description/meshes/rm_63_arm/S4C2_Link5.STL" />
        </geometry>
        <material
          name="">
          <color
            rgba="0.75294 0.75294 0.75294 1" />
        </material>
      </visual>
      <collision>
        <origin
          xyz="0 0 0"
          rpy="0 0 0" />
        <geometry>
          <mesh
            filename="package://rm_description/meshes/rm_63_arm/S4C2_Link5.STL" />
        </geometry>
      </collision>
    </link>
    <joint
      name="S4C2_Joint5"
      type="fixed">
      <origin
        xyz="0.0223 0.003 0.035591"
        rpy="0 0 0" />
      <parent
        link="S4C2_Link1" />
      <child
        link="S4C2_Link5" />
      <axis
        xyz="0 1 0" />
      <limit
        lower="0"
        upper="0.82"
        effort="1"
        velocity="1" />
      <mimic joint="S4C2_Joint1"/>
    </joint>
    <link
      name="S4C2_Link2">
      <inertial>
        <origin
          xyz="0.0087435 0.009 0.013955"
          rpy="0 0 0" />
        <mass
          value="0.00001" />
        <inertia
          ixx="5.6941E-07"
          ixy="-1.0711E-18"
          ixz="-2.6891E-07"
          iyy="6.2305E-07"
          iyz="-1.6845E-18"
          izz="3.0871E-07" />
      </inertial>
      <visual>
        <origin
          xyz="0 0 0"
          rpy="0 0 0" />
        <geometry>
          <mesh
            filename="package://rm_description/meshes/rm_63_arm/S4C2_Link2.STL" />
        </geometry>
        <material
          name="">
          <color
            rgba="0.75294 0.75294 0.75294 1" />
        </material>
      </visual>
      <collision>
        <origin
          xyz="0 0 0"
          rpy="0 0 0" />
        <geometry>
          <mesh
            filename="package://rm_description/meshes/rm_63_arm/S4C2_Link2.STL" />
        </geometry>
      </collision>
    </link>
    <joint
      name="S4C2_Joint2"
      type="fixed">
      <origin
        xyz="-0.03 -0.009 0.081"
        rpy="0 0 0" />
      <parent
        link="S4C2_baselink" />
      <child
        link="S4C2_Link2" />
      <axis
        xyz="0 -1 0" />
      <limit
        lower="0"
        upper="0.82"
        effort="1"
        velocity="1" />
      <mimic joint="S4C2_Joint1"/>
    </joint>
    <link
      name="S4C2_Link3">
      <inertial>
        <origin
          xyz="-0.0087435 0.009 0.013955"
          rpy="0 0 0" />
        <mass
          value="0.000001" />
        <inertia
          ixx="5.6941E-07"
          ixy="1.0666E-18"
          ixz="2.6891E-07"
          iyy="6.2305E-07"
          iyz="-1.8084E-18"
          izz="3.0871E-07" />
      </inertial>
      <visual>
        <origin
          xyz="0 0 0"
          rpy="0 0 0" />
        <geometry>
          <mesh
            filename="package://rm_description/meshes/rm_63_arm/S4C2_Link3.STL" />
        </geometry>
        <material
          name="">
          <color
            rgba="0.75294 0.75294 0.75294 1" />
        </material>
      </visual>
      <collision>
        <origin
          xyz="0 0 0"
          rpy="0 0 0" />
        <geometry>
          <mesh
            filename="package://rm_description/meshes/rm_63_arm/S4C2_Link3.STL" />
        </geometry>
      </collision>
    </link>
    <joint
      name="S4C2_Joint3"
      type="fixed">
      <origin
        xyz="0.03 -0.009 0.081"
        rpy="0 0 0" />
      <parent
        link="S4C2_baselink" />
      <child
        link="S4C2_Link3" />
      <axis
        xyz="0 -1 0" />
      <limit
        lower="-0.82"
        upper="0"
        effort="1"
        velocity="1" />
      <mimic joint="S4C2_Joint1" multiplier="-1"  offset="0"/>
    </joint>
    <link
      name="S4C2_Link4">
      <inertial>
        <origin
          xyz="-0.0087669 0.009 0.013992"
          rpy="0 0 0" />
        <mass
          value="0.000001" />
        <inertia
          ixx="5.1061E-07"
          ixy="-9.5279E-19"
          ixz="2.508E-07"
          iyy="5.7398E-07"
          iyz="7.6863E-19"
          izz="2.6747E-07" />
      </inertial>
      <visual>
        <origin
          xyz="0 0 0"
          rpy="0 0 0" />
        <geometry>
          <mesh
            filename="package://rm_description/meshes/rm_63_arm/S4C2_Link4.STL" />
        </geometry>
        <material
          name="">
          <color
            rgba="0.75294 0.75294 0.75294 1" />
        </material>
      </visual>
      <collision>
        <origin
          xyz="0 0 0"
          rpy="0 0 0" />
        <geometry>
          <mesh
            filename="package://rm_description/meshes/rm_63_arm/S4C2_Link4.STL" />
        </geometry>
      </collision>
    </link>
    <joint
      name="S4C2_Joint4"
      type="fixed">
      <origin
        xyz="0.04 -0.009 0.079"
        rpy="0 0 0" />
      <parent
        link="S4C2_baselink" />
      <child
        link="S4C2_Link4" />
      <axis
        xyz="0 -1 0" />
      <limit
        lower="-0.82"
        upper="0"
        effort="1"
        velocity="1" />
      <mimic joint="S4C2_Joint1" multiplier="-1"  offset="0"/>
    </joint>
    <link
      name="S4C2_Link6">
      <inertial>
        <origin
          xyz="-0.011864 0.006 0.011367"
          rpy="0 0 0" />
        <mass
          value="0.000001" />
        <inertia
          ixx="5.1288E-07"
          ixy="-9.8137E-14"
          ixz="9.4703E-08"
          iyy="5.3203E-07"
          iyz="6.2119E-14"
          izz="2.009E-07" />
      </inertial>
      <visual>
        <origin
          xyz="0 0 0"
          rpy="0 0 0" />
        <geometry>
          <mesh
            filename="package://rm_description/meshes/rm_63_arm/S4C2_Link6.STL" />
        </geometry>
        <material
          name="">
          <color
            rgba="0.75294 0.75294 0.75294 1" />
        </material>
      </visual>
      <collision>
        <origin
          xyz="0 0 0"
          rpy="0 0 0" />
        <geometry>
          <mesh
            filename="package://rm_description/meshes/rm_63_arm/S4C2_Link6.STL" />
        </geometry>
      </collision>
    </link>
    <joint
      name="S4C2_Joint6"
      type="fixed">
      <origin
        xyz="-0.0223 0.003 0.035591"
        rpy="0 0 0" />
      <parent
        link="S4C2_Link4" />
      <child
        link="S4C2_Link6" />
      <axis
        xyz="0 -1 0" />
      <limit
        lower="0"
        upper="0.82"
        effort="1"
        velocity="1" />
      <mimic joint="S4C2_Joint1"/>
    </joint>

</robot>
