<?xml version="1.0" encoding="utf-8"?>
<robot
  name="rml_63_description">
  <link
    name="base_link">
    <inertial>
      <origin
        xyz="0.0014231 -0.00010178 0.050147"
        rpy="0 0 0" />
      <mass
        value="0.66171" />
      <inertia
        ixx="0.00099443"
        ixy="3.282E-06"
        ixz="-9.9964E-06"
        iyy="0.0010144"
        iyz="1.2811E-06"
        izz="0.00067929" />
    </inertial>
    <visual>
      <origin
        xyz="0 0 0"
        rpy="0 0 0" />
      <geometry>
        <mesh
          filename="file://$(find rm_description)/meshes/rm_63_arm/base_link.STL" />
      </geometry>
      <material
        name="">
        <color
          rgba="1 1 1 1" />
      </material>
    </visual>
    <collision>
      <origin
        xyz="0 0 0"
        rpy="0 0 0" />
      <geometry>
        <mesh
          filename="file://$(find rm_description)/meshes/rm_63_arm/base_link.STL" />
      </geometry>
    </collision>
  </link>
  <link
    name="link1">
    <inertial>
      <origin
        xyz="-0.043281 -0.0072256 -0.012694"
        rpy="0 0 0" />
      <mass
        value="0.89496" />
      <inertia
        ixx="0.0010156"
        ixy="-0.00026764"
        ixz="0.00045014"
        iyy="0.0024107"
        iyz="6.0996E-05"
        izz="0.0022755" />
    </inertial>
    <visual>
      <origin
        xyz="0 0 0"
        rpy="0 0 0" />
      <geometry>
        <mesh
          filename="file://$(find rm_description)/meshes/rm_63_arm/link1.STL" />
      </geometry>
      <material
        name="">
        <color
          rgba="1 1 1 1" />
      </material>
    </visual>
    <collision>
      <origin
        xyz="0 0 0"
        rpy="0 0 0" />
      <geometry>
        <mesh
          filename="file://$(find rm_description)/meshes/rm_63_arm/link1.STL" />
      </geometry>
    </collision>
  </link>
  <joint
    name="joint1"
    type="revolute">
    <origin
      xyz="0 0 0.1625"
      rpy="0 0 0" />
    <parent
      link="base_link" />
    <child
      link="link1" />
    <axis
      xyz="0 0 1" />
    <limit
      lower="-3.106"
      upper="3.106"
      effort="60"
      velocity="3.14" />
  </joint>
  <link
    name="link2">
    <inertial>
      <origin
        xyz="0.17388 3.639E-07 -0.089966"
        rpy="0 0 0" />
      <mass
        value="1.5679" />
      <inertia
        ixx="0.0010615"
        ixy="-7.3371E-08"
        ixz="-0.00025488"
        iyy="0.03035"
        iyz="-1.6148E-08"
        izz="0.030485" />
    </inertial>
    <visual>
      <origin
        xyz="0 0 0"
        rpy="0 0 0" />
      <geometry>
        <mesh
          filename="file://$(find rm_description)/meshes/rm_63_arm/link2.STL" />
      </geometry>
      <material
        name="">
        <color
          rgba="1 1 1 1" />
      </material>
    </visual>
    <collision>
      <origin
        xyz="0 0 0"
        rpy="0 0 0" />
      <geometry>
        <mesh
          filename="file://$(find rm_description)/meshes/rm_63_arm/link2.STL" />
      </geometry>
    </collision>
  </link>
  <joint
    name="joint2"
    type="revolute">
    <origin
      xyz="-0.086 0 0"
      rpy="-1.5708 -1.5708 0" />
    <parent
      link="link1" />
    <child
      link="link2" />
    <axis
      xyz="0 0 1" />
    <limit
      lower="-3.106"
      upper="3.106"
      effort="60"
      velocity="3.14" />
  </joint>
  <link
    name="link3">
    <inertial>
      <origin
        xyz="0.035968 -0.020568 -0.0048526"
        rpy="0 0 0" />
      <mass
        value="0.67539" />
      <inertia
        ixx="0.00091144"
        ixy="0.00043238"
        ixz="-0.0001205"
        iyy="0.0012128"
        iyz="6.6376E-05"
        izz="0.0015231" />
    </inertial>
    <visual>
      <origin
        xyz="0 0 0"
        rpy="0 0 0" />
      <geometry>
        <mesh
          filename="file://$(find rm_description)/meshes/rm_63_arm/link3.STL" />
      </geometry>
      <material
        name="">
        <color
          rgba="1 1 1 1" />
      </material>
    </visual>
    <collision>
      <origin
        xyz="0 0 0"
        rpy="0 0 0" />
      <geometry>
        <mesh
          filename="file://$(find rm_description)/meshes/rm_63_arm/link3.STL" />
      </geometry>
    </collision>
  </link>
  <joint
    name="joint3"
    type="revolute">
    <origin
      xyz="0.38 0 -0.00030011"
      rpy="0 0 1.5708" />
    <parent
      link="link2" />
    <child
      link="link3" />
    <axis
      xyz="0 0 1" />
    <limit
      lower="-3.106"
      upper="2.53"
      effort="30"
      velocity="3.92" />
  </joint>
  <link
    name="link4">
    <inertial>
      <origin
        xyz="-2.0098E-06 -0.033559 -0.18296"
        rpy="0 0 0" />
      <mass
        value="0.69687" />
      <inertia
        ixx="0.0085449"
        ixy="4.7796E-08"
        ixz="-1.0943E-08"
        iyy="0.0080043"
        iyz="0.0020032"
        izz="0.00084216" />
    </inertial>
    <visual>
      <origin
        xyz="0 0 0"
        rpy="0 0 0" />
      <geometry>
        <mesh
          filename="file://$(find rm_description)/meshes/rm_63_arm/link4.STL" />
      </geometry>
      <material
        name="">
        <color
          rgba="1 1 1 1" />
      </material>
    </visual>
    <collision>
      <origin
        xyz="0 0 0"
        rpy="0 0 0" />
      <geometry>
        <mesh
          filename="file://$(find rm_description)/meshes/rm_63_arm/link4.STL" />
      </geometry>
    </collision>
  </link>
  <joint
    name="joint4"
    type="revolute">
    <origin
      xyz="0.069 -0.405 0.00029958"
      rpy="1.5708 0 0" />
    <parent
      link="link3" />
    <child
      link="link4" />
    <axis
      xyz="0 0 1" />
    <limit
      lower="-3.106"
      upper="3.106"
      effort="10"
      velocity="3.92" />
  </joint>
  <link
    name="link5">
    <inertial>
      <origin
        xyz="-1.5679E-07 0.02862 -0.0062118"
        rpy="0 0 0" />
      <mass
        value="0.34759" />
      <inertia
        ixx="0.00049457"
        ixy="-1.0235E-08"
        ixz="-1.8949E-09"
        iyy="0.00019706"
        iyz="-6.3439E-05"
        izz="0.00044565" />
    </inertial>
    <visual>
      <origin
        xyz="0 0 0"
        rpy="0 0 0" />
      <geometry>
        <mesh
          filename="file://$(find rm_description)/meshes/rm_63_arm/link5.STL" />
      </geometry>
      <material
        name="">
        <color
          rgba="1 1 1 1" />
      </material>
    </visual>
    <collision>
      <origin
        xyz="0 0 0"
        rpy="0 0 0" />
      <geometry>
        <mesh
          filename="file://$(find rm_description)/meshes/rm_63_arm/link5.STL" />
      </geometry>
    </collision>
  </link>
  <joint
    name="joint5"
    type="revolute">
    <origin
      xyz="0 0 0"
      rpy="1.5708 0 3.1416" />
    <parent
      link="link4" />
    <child
      link="link5" />
    <axis
      xyz="0 0 1" />
    <limit
      lower="-3.106"
      upper="3.106"
      effort="10"
      velocity="3.92" />
  </joint>
  <link
    name="link6">
    <inertial>
      <origin
        xyz="-0.0006163 0.00034085 -0.01449"
        rpy="0 0 0" />
      <mass
        value="0.077104" />
      <inertia
        ixx="2.2947E-05"
        ixy="-1.3061E-06"
        ixz="1.1202E-07"
        iyy="2.1475E-05"
        iyz="-5.1151E-08"
        izz="3.4243E-05" />
    </inertial>
    <visual>
      <origin
        xyz="0 0 0"
        rpy="0 0 0" />
      <geometry>
        <mesh
          filename="file://$(find rm_description)/meshes/rm_63_arm/link6.STL" />
      </geometry>
      <material
        name="">
        <color
          rgba="1 1 1 1" />
      </material>
    </visual>
    <collision>
      <origin
        xyz="0 0 0"
        rpy="0 0 0" />
      <geometry>
        <mesh
          filename="file://$(find rm_description)/meshes/rm_63_arm/link6.STL" />
      </geometry>
    </collision>
  </link>
  <joint
    name="joint6"
    type="revolute">
    <origin
      xyz="0 0.115 0"
      rpy="1.5708 0 3.1416" />
    <parent
      link="link5" />
    <child
      link="link6" />
    <axis
      xyz="0 0 1" />
    <limit
      lower="-6.28"
      upper="6.28"
      effort="10"
      velocity="3.92" />
  </joint>


    <!-- gripper -->
    <joint
      name="fixed_plate"
      type="fixed">
      <origin
        xyz="0 0 0"
        rpy="0 0 1.5708" />
      <parent
        link="link6" />
      <child
        link="S4C2_baselink" />
      <axis
        xyz="0 0 1" />
    </joint>

    <link
      name="S4C2_baselink">
      <inertial>
        <origin
          xyz="1.5645E-05 -4.1838E-06 0.038"
          rpy="0 0 0" />
        <mass
          value="0.00001" />
        <inertia
          ixx="5.095E-05"
          ixy="-7.3167E-13"
          ixz="2.0229E-08"
          iyy="6.0883E-05"
          iyz="-4.5583E-09"
          izz="1.933E-05" />
      </inertial>
      <visual>
        <origin
          xyz="0 0 0"
          rpy="0 0 0" />
        <geometry>
          <mesh
            filename="file://$(find rm_description)/meshes/rm_63_arm/S4C2_baselink.STL" />
        </geometry>
        <material
          name="">
          <color
            rgba="0.75294 0.75294 0.75294 1" />
        </material>
      </visual>
    </link>
    <link
      name="S4C2_Link1">
      <inertial>
        <origin
          xyz="0.0087669 0.009 0.013992"
          rpy="0 0 0" />
        <mass
          value="0.00001" />
        <inertia
          ixx="5.1061E-07"
          ixy="-8.6739E-19"
          ixz="-2.508E-07"
          iyy="5.7398E-07"
          iyz="-1.3667E-18"
          izz="2.6747E-07" />
      </inertial>
      <visual>
        <origin
          xyz="0 0 0"
          rpy="0 0 0" />
        <geometry>
          <mesh
            filename="file://$(find rm_description)/meshes/rm_63_arm/S4C2_Link1.STL" />
        </geometry>
        <material
          name="">
          <color
            rgba="0.75294 0.75294 0.75294 1" />
        </material>
      </visual>
    </link>
    <joint
      name="S4C2_Joint1"
      type="fixed">
      <origin
        xyz="-0.04 -0.009 0.079"
        rpy="0 0 0" />
      <parent
        link="S4C2_baselink" />
      <child
        link="S4C2_Link1" />
      <axis
        xyz="0 -1 0" />
      <limit
        lower="0"
        upper="0.82"
        effort="1"
        velocity="1" />
      
    </joint>
    <link
      name="S4C2_Link5">
      <inertial>
        <origin
          xyz="0.011864 0.006 0.011367"
          rpy="0 0 0" />
        <mass
          value="0.000045068" />
        <inertia
          ixx="5.1288E-07"
          ixy="-9.8137E-14"
          ixz="-9.4703E-08"
          iyy="5.3203E-07"
          iyz="-6.212E-14"
          izz="2.009E-07" />
      </inertial>
      <visual>
        <origin
          xyz="0 0 0"
          rpy="0 0 0" />
        <geometry>
          <mesh
            filename="file://$(find rm_description)/meshes/rm_63_arm/S4C2_Link5.STL" />
        </geometry>
        <material
          name="">
          <color
            rgba="0.75294 0.75294 0.75294 1" />
        </material>
      </visual>
    </link>
    <joint
      name="S4C2_Joint5"
      type="fixed">
      <origin
        xyz="0.0223 0.003 0.035591"
        rpy="0 0 0" />
      <parent
        link="S4C2_Link1" />
      <child
        link="S4C2_Link5" />
      <axis
        xyz="0 1 0" />
      <limit
        lower="0"
        upper="0.82"
        effort="1"
        velocity="1" />
      <mimic joint="S4C2_Joint1"/>
    </joint>
    <link
      name="S4C2_Link2">
      <inertial>
        <origin
          xyz="0.0087435 0.009 0.013955"
          rpy="0 0 0" />
        <mass
          value="0.00001" />
        <inertia
          ixx="5.6941E-07"
          ixy="-1.0711E-18"
          ixz="-2.6891E-07"
          iyy="6.2305E-07"
          iyz="-1.6845E-18"
          izz="3.0871E-07" />
      </inertial>
      <visual>
        <origin
          xyz="0 0 0"
          rpy="0 0 0" />
        <geometry>
          <mesh
            filename="file://$(find rm_description)/meshes/rm_63_arm/S4C2_Link2.STL" />
        </geometry>
        <material
          name="">
          <color
            rgba="0.75294 0.75294 0.75294 1" />
        </material>
      </visual>
    </link>
    <joint
      name="S4C2_Joint2"
      type="fixed">
      <origin
        xyz="-0.03 -0.009 0.081"
        rpy="0 0 0" />
      <parent
        link="S4C2_baselink" />
      <child
        link="S4C2_Link2" />
      <axis
        xyz="0 -1 0" />
      <limit
        lower="0"
        upper="0.82"
        effort="1"
        velocity="1" />
      <mimic joint="S4C2_Joint1"/>
    </joint>
    <link
      name="S4C2_Link3">
      <inertial>
        <origin
          xyz="-0.0087435 0.009 0.013955"
          rpy="0 0 0" />
        <mass
          value="0.000001" />
        <inertia
          ixx="5.6941E-07"
          ixy="1.0666E-18"
          ixz="2.6891E-07"
          iyy="6.2305E-07"
          iyz="-1.8084E-18"
          izz="3.0871E-07" />
      </inertial>
      <visual>
        <origin
          xyz="0 0 0"
          rpy="0 0 0" />
        <geometry>
          <mesh
            filename="file://$(find rm_description)/meshes/rm_63_arm/S4C2_Link3.STL" />
        </geometry>
        <material
          name="">
          <color
            rgba="0.75294 0.75294 0.75294 1" />
        </material>
      </visual>
    </link>
    <joint
      name="S4C2_Joint3"
      type="fixed">
      <origin
        xyz="0.03 -0.009 0.081"
        rpy="0 0 0" />
      <parent
        link="S4C2_baselink" />
      <child
        link="S4C2_Link3" />
      <axis
        xyz="0 -1 0" />
      <limit
        lower="-0.82"
        upper="0"
        effort="1"
        velocity="1" />
      <mimic joint="S4C2_Joint1" multiplier="-1"  offset="0"/>
    </joint>
    <link
      name="S4C2_Link4">
      <inertial>
        <origin
          xyz="-0.0087669 0.009 0.013992"
          rpy="0 0 0" />
        <mass
          value="0.000001" />
        <inertia
          ixx="5.1061E-07"
          ixy="-9.5279E-19"
          ixz="2.508E-07"
          iyy="5.7398E-07"
          iyz="7.6863E-19"
          izz="2.6747E-07" />
      </inertial>
      <visual>
        <origin
          xyz="0 0 0"
          rpy="0 0 0" />
        <geometry>
          <mesh
            filename="file://$(find rm_description)/meshes/rm_63_arm/S4C2_Link4.STL" />
        </geometry>
        <material
          name="">
          <color
            rgba="0.75294 0.75294 0.75294 1" />
        </material>
      </visual>
    </link>
    <joint
      name="S4C2_Joint4"
      type="fixed">
      <origin
        xyz="0.04 -0.009 0.079"
        rpy="0 0 0" />
      <parent
        link="S4C2_baselink" />
      <child
        link="S4C2_Link4" />
      <axis
        xyz="0 -1 0" />
      <limit
        lower="-0.82"
        upper="0"
        effort="1"
        velocity="1" />
      <mimic joint="S4C2_Joint1" multiplier="-1"  offset="0"/>
    </joint>
    <link
      name="S4C2_Link6">
      <inertial>
        <origin
          xyz="-0.011864 0.006 0.011367"
          rpy="0 0 0" />
        <mass
          value="0.000001" />
        <inertia
          ixx="5.1288E-07"
          ixy="-9.8137E-14"
          ixz="9.4703E-08"
          iyy="5.3203E-07"
          iyz="6.2119E-14"
          izz="2.009E-07" />
      </inertial>
      <visual>
        <origin
          xyz="0 0 0"
          rpy="0 0 0" />
        <geometry>
          <mesh
            filename="file://$(find rm_description)/meshes/rm_63_arm/S4C2_Link6.STL" />
        </geometry>
        <material
          name="">
          <color
            rgba="0.75294 0.75294 0.75294 1" />
        </material>
      </visual>
    </link>
    <joint
      name="S4C2_Joint6"
      type="fixed">
      <origin
        xyz="-0.0223 0.003 0.035591"
        rpy="0 0 0" />
      <parent
        link="S4C2_Link4" />
      <child
        link="S4C2_Link6" />
      <axis
        xyz="0 -1 0" />
      <limit
        lower="0"
        upper="0.82"
        effort="1"
        velocity="1" />
      <mimic joint="S4C2_Joint1"/>
    </joint>

</robot>
